Workbook
Name Slicer_Country: #N/A
Name Slicer_Customer_Type: #N/A
Name Slicer_Service: #N/A
Name Slicer_Year: #N/A

Sheet Dashboard

Sheet Input Data
A1: Country | B1: Year | C1: Service | D1: Customer Type | E1: Revenue | F1: Gross Profit | G1: EBITDA
A2: USA | B2: 2018 | C2: Artificial Intelligence | D2: SMB | E2: =INDEX('Financials USA'!$E$7:$N$19,MATCH('Input Data'!D2&C2,'Financials USA'!$A$7:$A$19,0),MATCH('Input Data'!B2,'Financials USA'!$E$1:$N$1,0)) -> 1869 | F2: =_xlfn.XLOOKUP(A2&B2&C2,'Gross Profit & EBITDA'!D:D,'Gross Profit & EBITDA'!E:E,"",0,1)*E2 -> 934.5 | G2: =_xlfn.XLOOKUP(A2&B2&C2,'Gross Profit & EBITDA'!D:D,'Gross Profit & EBITDA'!F:F,"",0,1)*E2 -> 373.8 | O2: Year | P2: (All)
A3: USA | B3: 2018 | C3: Artificial Intelligence | D3: Enterprise | E3: =INDEX('Financials USA'!$E$7:$N$19,MATCH('Input Data'!D3&C3,'Financials USA'!$A$7:$A$19,0),MATCH('Input Data'!B3,'Financials USA'!$E$1:$N$1,0)) -> 23961 | F3: =_xlfn.XLOOKUP(A3&B3&C3,'Gross Profit & EBITDA'!D:D,'Gross Profit & EBITDA'!E:E,"",0,1)*E3 -> 11980.5 | G3: =_xlfn.XLOOKUP(A3&B3&C3,'Gross Profit & EBITDA'!D:D,'Gross Profit & EBITDA'!F:F,"",0,1)*E3 -> 4792.2 | J3: Service | K3: (All) | O3: Service | P3: (All)
A4: USA | B4: 2018 | C4: Marketing | D4: SMB | E4: =INDEX('Financials USA'!$E$7:$N$19,MATCH('Input Data'!D4&C4,'Financials USA'!$A$7:$A$19,0),MATCH('Input Data'!B4,'Financials USA'!$E$1:$N$1,0)) -> 5607 | F4: =_xlfn.XLOOKUP(A4&B4&C4,'Gross Profit & EBITDA'!D:D,'Gross Profit & EBITDA'!E:E,"",0,1)*E4 -> 3924.9 | G4: =_xlfn.XLOOKUP(A4&B4&C4,'Gross Profit & EBITDA'!D:D,'Gross Profit & EBITDA'!F:F,"",0,1)*E4 -> 1121.4 | J4: Customer Type | K4: (All) | O4: Customer Type | P4: (All)
A5: USA | B5: 2018 | C5: Marketing | D5: Enterprise | E5: =INDEX('Financials USA'!$E$7:$N$19,MATCH('Input Data'!D5&C5,'Financials USA'!$A$7:$A$19,0),MATCH('Input Data'!B5,'Financials USA'!$E$1:$N$1,0)) -> 23961 | F5: =_xlfn.XLOOKUP(A5&B5&C5,'Gross Profit & EBITDA'!D:D,'Gross Profit & EBITDA'!E:E,"",0,1)*E5 -> 16772.7 | G5: =_xlfn.XLOOKUP(A5&B5&C5,'Gross Profit & EBITDA'!D:D,'Gross Profit & EBITDA'!F:F,"",0,1)*E5 -> 4792.2
A6: USA | B6: 2018 | C6: Accounting | D6: SMB | E6: =INDEX('Financials USA'!$E$7:$N$19,MATCH('Input Data'!D6&C6,'Financials USA'!$A$7:$A$19,0),MATCH('Input Data'!B6,'Financials USA'!$E$1:$N$1,0)) -> 684 | F6: =_xlfn.XLOOKUP(A6&B6&C6,'Gross Profit & EBITDA'!D:D,'Gross Profit & EBITDA'!E:E,"",0,1)*E6 -> 478.8 | G6: =_xlfn.XLOOKUP(A6&B6&C6,'Gross Profit & EBITDA'!D:D,'Gross Profit & EBITDA'!F:F,"",0,1)*E6 -> 68.4 | J6: Row Labels | K6: Revenue | L6: EBITDA | O6: Values
A7: USA | B7: 2018 | C7: Accounting | D7: Enterprise | E7: =INDEX('Financials USA'!$E$7:$N$19,MATCH('Input Data'!D7&C7,'Financials USA'!$A$7:$A$19,0),MATCH('Input Data'!B7,'Financials USA'!$E$1:$N$1,0)) -> 9098 | F7: =_xlfn.XLOOKUP(A7&B7&C7,'Gross Profit & EBITDA'!D:D,'Gross Profit & EBITDA'!E:E,"",0,1)*E7 -> 6368.6 | G7: =_xlfn.XLOOKUP(A7&B7&C7,'Gross Profit & EBITDA'!D:D,'Gross Profit & EBITDA'!F:F,"",0,1)*E7 -> 909.8 | J7: 2018 | K7: 172710 | L7: 31368.4 | O7: Sum of Gross Profit | P7: 2075197.2
A8: USA | B8: 2019 | C8: Artificial Intelligence | D8: SMB | E8: =INDEX('Financials USA'!$E$7:$N$19,MATCH('Input Data'!D8&C8,'Financials USA'!$A$7:$A$19,0),MATCH('Input Data'!B8,'Financials USA'!$E$1:$N$1,0)) -> 3211 | F8: =_xlfn.XLOOKUP(A8&B8&C8,'Gross Profit & EBITDA'!D:D,'Gross Profit & EBITDA'!E:E,"",0,1)*E8 -> 1605.5 | G8: =_xlfn.XLOOKUP(A8&B8&C8,'Gross Profit & EBITDA'!D:D,'Gross Profit & EBITDA'!F:F,"",0,1)*E8 -> 321.1 | J8: 2019 | K8: 372232 | L8: 47960.8 | O8: Sum of Difference Revenue/Gross Profit | P8: 1369606.8
A9: USA | B9: 2019 | C9: Artificial Intelligence | D9: Enterprise | E9: =INDEX('Financials USA'!$E$7:$N$19,MATCH('Input Data'!D9&C9,'Financials USA'!$A$7:$A$19,0),MATCH('Input Data'!B9,'Financials USA'!$E$1:$N$1,0)) -> 15956 | F9: =_xlfn.XLOOKUP(A9&B9&C9,'Gross Profit & EBITDA'!D:D,'Gross Profit & EBITDA'!E:E,"",0,1)*E9 -> 7978 | G9: =_xlfn.XLOOKUP(A9&B9&C9,'Gross Profit & EBITDA'!D:D,'Gross Profit & EBITDA'!F:F,"",0,1)*E9 -> 1595.6 | J9: 2020 | K9: 253994 | L9: 44749.4
A10: USA | B10: 2019 | C10: Marketing | D10: SMB | E10: =INDEX('Financials USA'!$E$7:$N$19,MATCH('Input Data'!D10&C10,'Financials USA'!$A$7:$A$19,0),MATCH('Input Data'!B10,'Financials USA'!$E$1:$N$1,0)) -> 12844 | F10: =_xlfn.XLOOKUP(A10&B10&C10,'Gross Profit & EBITDA'!D:D,'Gross Profit & EBITDA'!E:E,"",0,1)*E10 -> 6422 | G10: =_xlfn.XLOOKUP(A10&B10&C10,'Gross Profit & EBITDA'!D:D,'Gross Profit & EBITDA'!F:F,"",0,1)*E10 -> 1284.4 | J10: 2021 | K10: 341092 | L10: 43972.4 | O10: Gross Margin | P10: =GETPIVOTDATA("Sum of Gross Profit",$O$6)/SUM(P7:P8) -> 0.60241372
A11: USA | B11: 2019 | C11: Marketing | D11: Enterprise | E11: =INDEX('Financials USA'!$E$7:$N$19,MATCH('Input Data'!D11&C11,'Financials USA'!$A$7:$A$19,0),MATCH('Input Data'!B11,'Financials USA'!$E$1:$N$1,0)) -> 95736 | F11: =_xlfn.XLOOKUP(A11&B11&C11,'Gross Profit & EBITDA'!D:D,'Gross Profit & EBITDA'!E:E,"",0,1)*E11 -> 47868 | G11: =_xlfn.XLOOKUP(A11&B11&C11,'Gross Profit & EBITDA'!D:D,'Gross Profit & EBITDA'!F:F,"",0,1)*E11 -> 9573.6 | J11: 2022 | K11: 362808 | L11: 39367.8
A12: USA | B12: 2019 | C12: Accounting | D12: SMB | E12: =INDEX('Financials USA'!$E$7:$N$19,MATCH('Input Data'!D12&C12,'Financials USA'!$A$7:$A$19,0),MATCH('Input Data'!B12,'Financials USA'!$E$1:$N$1,0)) -> 17682 | F12: =_xlfn.XLOOKUP(A12&B12&C12,'Gross Profit & EBITDA'!D:D,'Gross Profit & EBITDA'!E:E,"",0,1)*E12 -> 10609.2 | G12: =_xlfn.XLOOKUP(A12&B12&C12,'Gross Profit & EBITDA'!D:D,'Gross Profit & EBITDA'!F:F,"",0,1)*E12 -> 3536.4 | J12: 2023 | K12: 396536 | L12: 73539.2
A13: USA | B13: 2019 | C13: Accounting | D13: Enterprise | E13: =INDEX('Financials USA'!$E$7:$N$19,MATCH('Input Data'!D13&C13,'Financials USA'!$A$7:$A$19,0),MATCH('Input Data'!B13,'Financials USA'!$E$1:$N$1,0)) -> 19683 | F13: =_xlfn.XLOOKUP(A13&B13&C13,'Gross Profit & EBITDA'!D:D,'Gross Profit & EBITDA'!E:E,"",0,1)*E13 -> 11809.8 | G13: =_xlfn.XLOOKUP(A13&B13&C13,'Gross Profit & EBITDA'!D:D,'Gross Profit & EBITDA'!F:F,"",0,1)*E13 -> 3936.6 | J13: 2024 | K13: 316422 | L13: 37103.2 | O13: Year | P13: (All)
A14: USA | B14: 2020 | C14: Artificial Intelligence | D14: SMB | E14: =INDEX('Financials USA'!$E$7:$N$19,MATCH('Input Data'!D14&C14,'Financials USA'!$A$7:$A$19,0),MATCH('Input Data'!B14,'Financials USA'!$E$1:$N$1,0)) -> 4810 | F14: =_xlfn.XLOOKUP(A14&B14&C14,'Gross Profit & EBITDA'!D:D,'Gross Profit & EBITDA'!E:E,"",0,1)*E14 -> 3848 | G14: =_xlfn.XLOOKUP(A14&B14&C14,'Gross Profit & EBITDA'!D:D,'Gross Profit & EBITDA'!F:F,"",0,1)*E14 -> 962 | J14: 2025 | K14: 397088 | L14: 70410 | O14: Service | P14: (All)
A15: USA | B15: 2020 | C15: Artificial Intelligence | D15: Enterprise | E15: =INDEX('Financials USA'!$E$7:$N$19,MATCH('Input Data'!D15&C15,'Financials USA'!$A$7:$A$19,0),MATCH('Input Data'!B15,'Financials USA'!$E$1:$N$1,0)) -> 16090 | F15: =_xlfn.XLOOKUP(A15&B15&C15,'Gross Profit & EBITDA'!D:D,'Gross Profit & EBITDA'!E:E,"",0,1)*E15 -> 12872 | G15: =_xlfn.XLOOKUP(A15&B15&C15,'Gross Profit & EBITDA'!D:D,'Gross Profit & EBITDA'!F:F,"",0,1)*E15 -> 3218 | J15: 2026 | K15: 384896 | L15: 73763.2 | O15: Customer Type | P15: (All)
A16: USA | B16: 2020 | C16: Marketing | D16: SMB | E16: =INDEX('Financials USA'!$E$7:$N$19,MATCH('Input Data'!D16&C16,'Financials USA'!$A$7:$A$19,0),MATCH('Input Data'!B16,'Financials USA'!$E$1:$N$1,0)) -> 9620 | F16: =_xlfn.XLOOKUP(A16&B16&C16,'Gross Profit & EBITDA'!D:D,'Gross Profit & EBITDA'!E:E,"",0,1)*E16 -> 4810 | G16: =_xlfn.XLOOKUP(A16&B16&C16,'Gross Profit & EBITDA'!D:D,'Gross Profit & EBITDA'!F:F,"",0,1)*E16 -> 962 | J16: 2027 | K16: 447026 | L16: 81941.4
A17: USA | B17: 2020 | C17: Marketing | D17: Enterprise | E17: =INDEX('Financials USA'!$E$7:$N$19,MATCH('Input Data'!D17&C17,'Financials USA'!$A$7:$A$19,0),MATCH('Input Data'!B17,'Financials USA'!$E$1:$N$1,0)) -> 16090 | F17: =_xlfn.XLOOKUP(A17&B17&C17,'Gross Profit & EBITDA'!D:D,'Gross Profit & EBITDA'!E:E,"",0,1)*E17 -> 8045 | G17: =_xlfn.XLOOKUP(A17&B17&C17,'Gross Profit & EBITDA'!D:D,'Gross Profit & EBITDA'!F:F,"",0,1)*E17 -> 1609 | J17: Grand Total | K17: 3444804 | L17: 544175.8 | O17: Values
A18: USA | B18: 2020 | C18: Accounting | D18: SMB | E18: =INDEX('Financials USA'!$E$7:$N$19,MATCH('Input Data'!D18&C18,'Financials USA'!$A$7:$A$19,0),MATCH('Input Data'!B18,'Financials USA'!$E$1:$N$1,0)) -> 10140 | F18: =_xlfn.XLOOKUP(A18&B18&C18,'Gross Profit & EBITDA'!D:D,'Gross Profit & EBITDA'!E:E,"",0,1)*E18 -> 8112 | G18: =_xlfn.XLOOKUP(A18&B18&C18,'Gross Profit & EBITDA'!D:D,'Gross Profit & EBITDA'!F:F,"",0,1)*E18 -> 2028 | O18: Sum of EBITDA | P18: 544175.8
A19: USA | B19: 2020 | C19: Accounting | D19: Enterprise | E19: =INDEX('Financials USA'!$E$7:$N$19,MATCH('Input Data'!D19&C19,'Financials USA'!$A$7:$A$19,0),MATCH('Input Data'!B19,'Financials USA'!$E$1:$N$1,0)) -> 55827 | F19: =_xlfn.XLOOKUP(A19&B19&C19,'Gross Profit & EBITDA'!D:D,'Gross Profit & EBITDA'!E:E,"",0,1)*E19 -> 44661.6 | G19: =_xlfn.XLOOKUP(A19&B19&C19,'Gross Profit & EBITDA'!D:D,'Gross Profit & EBITDA'!F:F,"",0,1)*E19 -> 11165.4 | O19: Sum of Difference Revenue/EBIDTA | P19: 2900628.2
A20: USA | B20: 2021 | C20: Artificial Intelligence | D20: SMB | E20: =INDEX('Financials USA'!$E$7:$N$19,MATCH('Input Data'!D20&C20,'Financials USA'!$A$7:$A$19,0),MATCH('Input Data'!B20,'Financials USA'!$E$1:$N$1,0)) -> 7470 | F20: =_xlfn.XLOOKUP(A20&B20&C20,'Gross Profit & EBITDA'!D:D,'Gross Profit & EBITDA'!E:E,"",0,1)*E20 -> 4482 | G20: =_xlfn.XLOOKUP(A20&B20&C20,'Gross Profit & EBITDA'!D:D,'Gross Profit & EBITDA'!F:F,"",0,1)*E20 -> 1494
A21: USA | B21: 2021 | C21: Artificial Intelligence | D21: Enterprise | E21: =INDEX('Financials USA'!$E$7:$N$19,MATCH('Input Data'!D21&C21,'Financials USA'!$A$7:$A$19,0),MATCH('Input Data'!B21,'Financials USA'!$E$1:$N$1,0)) -> 15225 | F21: =_xlfn.XLOOKUP(A21&B21&C21,'Gross Profit & EBITDA'!D:D,'Gross Profit & EBITDA'!E:E,"",0,1)*E21 -> 9135 | G21: =_xlfn.XLOOKUP(A21&B21&C21,'Gross Profit & EBITDA'!D:D,'Gross Profit & EBITDA'!F:F,"",0,1)*E21 -> 3045 | O21: EBIDTA Margin | P21: =GETPIVOTDATA("Sum of EBITDA",$O$17)/SUM(P18:P19) -> 0.15797003
A22: USA | B22: 2021 | C22: Marketing | D22: SMB | E22: =INDEX('Financials USA'!$E$7:$N$19,MATCH('Input Data'!D22&C22,'Financials USA'!$A$7:$A$19,0),MATCH('Input Data'!B22,'Financials USA'!$E$1:$N$1,0)) -> 29880 | F22: =_xlfn.XLOOKUP(A22&B22&C22,'Gross Profit & EBITDA'!D:D,'Gross Profit & EBITDA'!E:E,"",0,1)*E22 -> 20916 | G22: =_xlfn.XLOOKUP(A22&B22&C22,'Gross Profit & EBITDA'!D:D,'Gross Profit & EBITDA'!F:F,"",0,1)*E22 -> 2988 | J22: Row Labels | K22: Sum of Revenue
A23: USA | B23: 2021 | C23: Marketing | D23: Enterprise | E23: =INDEX('Financials USA'!$E$7:$N$19,MATCH('Input Data'!D23&C23,'Financials USA'!$A$7:$A$19,0),MATCH('Input Data'!B23,'Financials USA'!$E$1:$N$1,0)) -> 91350 | F23: =_xlfn.XLOOKUP(A23&B23&C23,'Gross Profit & EBITDA'!D:D,'Gross Profit & EBITDA'!E:E,"",0,1)*E23 -> 63945 | G23: =_xlfn.XLOOKUP(A23&B23&C23,'Gross Profit & EBITDA'!D:D,'Gross Profit & EBITDA'!F:F,"",0,1)*E23 -> 9135 | J23: USA | K23: 2977048
A24: USA | B24: 2021 | C24: Accounting | D24: SMB | E24: =INDEX('Financials USA'!$E$7:$N$19,MATCH('Input Data'!D24&C24,'Financials USA'!$A$7:$A$19,0),MATCH('Input Data'!B24,'Financials USA'!$E$1:$N$1,0)) -> 3252 | F24: =_xlfn.XLOOKUP(A24&B24&C24,'Gross Profit & EBITDA'!D:D,'Gross Profit & EBITDA'!E:E,"",0,1)*E24 -> 2601.6 | G24: =_xlfn.XLOOKUP(A24&B24&C24,'Gross Profit & EBITDA'!D:D,'Gross Profit & EBITDA'!F:F,"",0,1)*E24 -> 650.4 | J24: Grand Total | K24: 2977048
A25: USA | B25: 2021 | C25: Accounting | D25: Enterprise | E25: =INDEX('Financials USA'!$E$7:$N$19,MATCH('Input Data'!D25&C25,'Financials USA'!$A$7:$A$19,0),MATCH('Input Data'!B25,'Financials USA'!$E$1:$N$1,0)) -> 6756 | F25: =_xlfn.XLOOKUP(A25&B25&C25,'Gross Profit & EBITDA'!D:D,'Gross Profit & EBITDA'!E:E,"",0,1)*E25 -> 5404.8 | G25: =_xlfn.XLOOKUP(A25&B25&C25,'Gross Profit & EBITDA'!D:D,'Gross Profit & EBITDA'!F:F,"",0,1)*E25 -> 1351.2
A26: USA | B26: 2022 | C26: Artificial Intelligence | D26: SMB | E26: =INDEX('Financials USA'!$E$7:$N$19,MATCH('Input Data'!D26&C26,'Financials USA'!$A$7:$A$19,0),MATCH('Input Data'!B26,'Financials USA'!$E$1:$N$1,0)) -> 11367 | F26: =_xlfn.XLOOKUP(A26&B26&C26,'Gross Profit & EBITDA'!D:D,'Gross Profit & EBITDA'!E:E,"",0,1)*E26 -> 7956.9 | G26: =_xlfn.XLOOKUP(A26&B26&C26,'Gross Profit & EBITDA'!D:D,'Gross Profit & EBITDA'!F:F,"",0,1)*E26 -> 1136.7
A27: USA | B27: 2022 | C27: Artificial Intelligence | D27: Enterprise | E27: =INDEX('Financials USA'!$E$7:$N$19,MATCH('Input Data'!D27&C27,'Financials USA'!$A$7:$A$19,0),MATCH('Input Data'!B27,'Financials USA'!$E$1:$N$1,0)) -> 14484 | F27: =_xlfn.XLOOKUP(A27&B27&C27,'Gross Profit & EBITDA'!D:D,'Gross Profit & EBITDA'!E:E,"",0,1)*E27 -> 10138.8 | G27: =_xlfn.XLOOKUP(A27&B27&C27,'Gross Profit & EBITDA'!D:D,'Gross Profit & EBITDA'!F:F,"",0,1)*E27 -> 1448.4 | J27: Country | K27: Revenue
A28: USA | B28: 2022 | C28: Marketing | D28: SMB | E28: =INDEX('Financials USA'!$E$7:$N$19,MATCH('Input Data'!D28&C28,'Financials USA'!$A$7:$A$19,0),MATCH('Input Data'!B28,'Financials USA'!$E$1:$N$1,0)) -> 22734 | F28: =_xlfn.XLOOKUP(A28&B28&C28,'Gross Profit & EBITDA'!D:D,'Gross Profit & EBITDA'!E:E,"",0,1)*E28 -> 11367 | G28: =_xlfn.XLOOKUP(A28&B28&C28,'Gross Profit & EBITDA'!D:D,'Gross Profit & EBITDA'!F:F,"",0,1)*E28 -> 2273.4 | J28: Canada | K28: 467756
A29: USA | B29: 2022 | C29: Marketing | D29: Enterprise | E29: =INDEX('Financials USA'!$E$7:$N$19,MATCH('Input Data'!D29&C29,'Financials USA'!$A$7:$A$19,0),MATCH('Input Data'!B29,'Financials USA'!$E$1:$N$1,0)) -> 86904 | F29: =_xlfn.XLOOKUP(A29&B29&C29,'Gross Profit & EBITDA'!D:D,'Gross Profit & EBITDA'!E:E,"",0,1)*E29 -> 43452 | G29: =_xlfn.XLOOKUP(A29&B29&C29,'Gross Profit & EBITDA'!D:D,'Gross Profit & EBITDA'!F:F,"",0,1)*E29 -> 8690.4 | J29: USA | K29: 2977048
A30: USA | B30: 2022 | C30: Accounting | D30: SMB | E30: =INDEX('Financials USA'!$E$7:$N$19,MATCH('Input Data'!D30&C30,'Financials USA'!$A$7:$A$19,0),MATCH('Input Data'!B30,'Financials USA'!$E$1:$N$1,0)) -> 3515 | F30: =_xlfn.XLOOKUP(A30&B30&C30,'Gross Profit & EBITDA'!D:D,'Gross Profit & EBITDA'!E:E,"",0,1)*E30 -> 2812 | G30: =_xlfn.XLOOKUP(A30&B30&C30,'Gross Profit & EBITDA'!D:D,'Gross Profit & EBITDA'!F:F,"",0,1)*E30 -> 351.5
A31: USA | B31: 2022 | C31: Accounting | D31: Enterprise | E31: =INDEX('Financials USA'!$E$7:$N$19,MATCH('Input Data'!D31&C31,'Financials USA'!$A$7:$A$19,0),MATCH('Input Data'!B31,'Financials USA'!$E$1:$N$1,0)) -> 18760 | F31: =_xlfn.XLOOKUP(A31&B31&C31,'Gross Profit & EBITDA'!D:D,'Gross Profit & EBITDA'!E:E,"",0,1)*E31 -> 15008 | G31: =_xlfn.XLOOKUP(A31&B31&C31,'Gross Profit & EBITDA'!D:D,'Gross Profit & EBITDA'!F:F,"",0,1)*E31 -> 1876
A32: USA | B32: 2023 | C32: Artificial Intelligence | D32: SMB | E32: =INDEX('Financials USA'!$E$7:$N$19,MATCH('Input Data'!D32&C32,'Financials USA'!$A$7:$A$19,0),MATCH('Input Data'!B32,'Financials USA'!$E$1:$N$1,0)) -> 6894 | F32: =_xlfn.XLOOKUP(A32&B32&C32,'Gross Profit & EBITDA'!D:D,'Gross Profit & EBITDA'!E:E,"",0,1)*E32 -> 4825.8 | G32: =_xlfn.XLOOKUP(A32&B32&C32,'Gross Profit & EBITDA'!D:D,'Gross Profit & EBITDA'!F:F,"",0,1)*E32 -> 1378.8
A33: USA | B33: 2023 | C33: Artificial Intelligence | D33: Enterprise | E33: =INDEX('Financials USA'!$E$7:$N$19,MATCH('Input Data'!D33&C33,'Financials USA'!$A$7:$A$19,0),MATCH('Input Data'!B33,'Financials USA'!$E$1:$N$1,0)) -> 18660 | F33: =_xlfn.XLOOKUP(A33&B33&C33,'Gross Profit & EBITDA'!D:D,'Gross Profit & EBITDA'!E:E,"",0,1)*E33 -> 13062 | G33: =_xlfn.XLOOKUP(A33&B33&C33,'Gross Profit & EBITDA'!D:D,'Gross Profit & EBITDA'!F:F,"",0,1)*E33 -> 3732 | J33: Country | K33: (All)
A34: USA | B34: 2023 | C34: Marketing | D34: SMB | E34: =INDEX('Financials USA'!$E$7:$N$19,MATCH('Input Data'!D34&C34,'Financials USA'!$A$7:$A$19,0),MATCH('Input Data'!B34,'Financials USA'!$E$1:$N$1,0)) -> 13788 | F34: =_xlfn.XLOOKUP(A34&B34&C34,'Gross Profit & EBITDA'!D:D,'Gross Profit & EBITDA'!E:E,"",0,1)*E34 -> 9651.6 | G34: =_xlfn.XLOOKUP(A34&B34&C34,'Gross Profit & EBITDA'!D:D,'Gross Profit & EBITDA'!F:F,"",0,1)*E34 -> 2757.6 | J34: Year | K34: (All)
A35: USA | B35: 2023 | C35: Marketing | D35: Enterprise | E35: =INDEX('Financials USA'!$E$7:$N$19,MATCH('Input Data'!D35&C35,'Financials USA'!$A$7:$A$19,0),MATCH('Input Data'!B35,'Financials USA'!$E$1:$N$1,0)) -> 111960 | F35: =_xlfn.XLOOKUP(A35&B35&C35,'Gross Profit & EBITDA'!D:D,'Gross Profit & EBITDA'!E:E,"",0,1)*E35 -> 78372 | G35: =_xlfn.XLOOKUP(A35&B35&C35,'Gross Profit & EBITDA'!D:D,'Gross Profit & EBITDA'!F:F,"",0,1)*E35 -> 22392 | J35: Customer Type | K35: (All)
A36: USA | B36: 2023 | C36: Accounting | D36: SMB | E36: =INDEX('Financials USA'!$E$7:$N$19,MATCH('Input Data'!D36&C36,'Financials USA'!$A$7:$A$19,0),MATCH('Input Data'!B36,'Financials USA'!$E$1:$N$1,0)) -> 5064 | F36: =_xlfn.XLOOKUP(A36&B36&C36,'Gross Profit & EBITDA'!D:D,'Gross Profit & EBITDA'!E:E,"",0,1)*E36 -> 4051.2 | G36: =_xlfn.XLOOKUP(A36&B36&C36,'Gross Profit & EBITDA'!D:D,'Gross Profit & EBITDA'!F:F,"",0,1)*E36 -> 506.4
A37: USA | B37: 2023 | C37: Accounting | D37: Enterprise | E37: =INDEX('Financials USA'!$E$7:$N$19,MATCH('Input Data'!D37&C37,'Financials USA'!$A$7:$A$19,0),MATCH('Input Data'!B37,'Financials USA'!$E$1:$N$1,0)) -> 15933 | F37: =_xlfn.XLOOKUP(A37&B37&C37,'Gross Profit & EBITDA'!D:D,'Gross Profit & EBITDA'!E:E,"",0,1)*E37 -> 12746.4 | G37: =_xlfn.XLOOKUP(A37&B37&C37,'Gross Profit & EBITDA'!D:D,'Gross Profit & EBITDA'!F:F,"",0,1)*E37 -> 1593.3 | J37: Row Labels | K37: Revenue | L37: Gross Profit | M37: EBITDA
A38: USA | B38: 2024 | C38: Artificial Intelligence | D38: SMB | E38: =INDEX('Financials USA'!$E$7:$N$19,MATCH('Input Data'!D38&C38,'Financials USA'!$A$7:$A$19,0),MATCH('Input Data'!B38,'Financials USA'!$E$1:$N$1,0)) -> 8880 | F38: =_xlfn.XLOOKUP(A38&B38&C38,'Gross Profit & EBITDA'!D:D,'Gross Profit & EBITDA'!E:E,"",0,1)*E38 -> 4440 | G38: =_xlfn.XLOOKUP(A38&B38&C38,'Gross Profit & EBITDA'!D:D,'Gross Profit & EBITDA'!F:F,"",0,1)*E38 -> 1776 | J38: Accounting | K38: 766694 | L38: 497113.8 | M38: 131267
A39: USA | B39: 2024 | C39: Artificial Intelligence | D39: Enterprise | E39: =INDEX('Financials USA'!$E$7:$N$19,MATCH('Input Data'!D39&C39,'Financials USA'!$A$7:$A$19,0),MATCH('Input Data'!B39,'Financials USA'!$E$1:$N$1,0)) -> 13958 | F39: =_xlfn.XLOOKUP(A39&B39&C39,'Gross Profit & EBITDA'!D:D,'Gross Profit & EBITDA'!E:E,"",0,1)*E39 -> 6979 | G39: =_xlfn.XLOOKUP(A39&B39&C39,'Gross Profit & EBITDA'!D:D,'Gross Profit & EBITDA'!F:F,"",0,1)*E39 -> 2791.6 | J39: Artificial Intelligence | K39: 701974 | L39: 416295 | M39: 114326.6
A40: USA | B40: 2024 | C40: Marketing | D40: SMB | E40: =INDEX('Financials USA'!$E$7:$N$19,MATCH('Input Data'!D40&C40,'Financials USA'!$A$7:$A$19,0),MATCH('Input Data'!B40,'Financials USA'!$E$1:$N$1,0)) -> 53280 | F40: =_xlfn.XLOOKUP(A40&B40&C40,'Gross Profit & EBITDA'!D:D,'Gross Profit & EBITDA'!E:E,"",0,1)*E40 -> 26640 | G40: =_xlfn.XLOOKUP(A40&B40&C40,'Gross Profit & EBITDA'!D:D,'Gross Profit & EBITDA'!F:F,"",0,1)*E40 -> 5328 | J40: Marketing | K40: 1976136 | L40: 1161788.4 | M40: 298582.2
...

Sheet Financials USA
D1: Year | E1: 2018 | F1: 2019 | G1: 2020 | H1: 2021 | I1: 2022 | J1: 2023 | K1: 2024 | L1: 2025 | M1: 2026 | N1: 2027
D2: Period start | F2: 43466 | G2: 43831 | H2: 44197 | I2: 44562 | J2: 44927 | K2: 45292 | L2: 45658 | M2: 46023 | N2: 46388
D3: Period end | E3: 43465 | F3: 43830 | G3: 44196 | H3: 44561 | I3: 44926 | J3: 45291 | K3: 45657 | L3: 46022 | M3: 46387 | N3: 46752
A6: Index Key | B6: Customer | C6: Service
A7: =B7&C7 -> SMBArtificial Intelligence | B7: SMB | C7: Artificial Intelligence | E7: 1869 | F7: 3211 | G7: 4810 | H7: 7470 | I7: 11367 | J7: 6894 | K7: 8880 | L7: 4901 | M7: 3828 | N7: 5424
A8: =B8&C8 -> EnterpriseArtificial Intelligence | B8: Enterprise | C8: Artificial Intelligence | E8: 23961 | F8: 15956 | G8: 16090 | H8: 15225 | I8: 14484 | J8: 18660 | K8: 13958 | L8: 26427 | M8: 24219 | N8: 23442
C9: Total | E9: =SUM(E7:E8) -> 25830 | F9: =SUM(F7:F8) -> 19167 | G9: =SUM(G7:G8) -> 20900 | H9: =SUM(H7:H8) -> 22695 | I9: =SUM(I7:I8) -> 25851 | J9: =SUM(J7:J8) -> 25554 | K9: =SUM(K7:K8) -> 22838 | L9: =SUM(L7:L8) -> 31328 | ... N9: =SUM(N7:N8) -> 28866
A10: =B10&C10
A11: =B11&C11
A12: =B12&C12 -> SMBMarketing | B12: SMB | C12: Marketing | E12: 5607 | F12: 12844 | G12: 9620 | H12: 29880 | I12: 22734 | J12: 13788 | K12: 53280 | L12: 14703 | M12: 3828 | N12: 5424
A13: =B13&C13 -> EnterpriseMarketing | B13: Enterprise | C13: Marketing | E13: 23961 | F13: 95736 | G13: 16090 | H13: 91350 | I13: 86904 | J13: 111960 | K13: 41874 | L13: 52854 | M13: 96876 | N13: 140652
C14: Total | E14: =SUM(E12:E13) -> 29568 | F14: =SUM(F12:F13) -> 108580 | G14: =SUM(G12:G13) -> 25710 | H14: =SUM(H12:H13) -> 121230 | I14: =SUM(I12:I13) -> 109638 | J14: =SUM(J12:J13) -> 125748 | K14: =SUM(K12:K13) -> 95154 | L14: =SUM(L12:L13) -> 67557 | ... N14: =SUM(N12:N13) -> 146076
A15: =B15&C15
A16: =B16&C16
A17: =B17&C17
A18: =B18&C18 -> SMBAccounting | B18: SMB | C18: Accounting | E18: 684 | F18: 17682 | G18: 10140 | H18: 3252 | I18: 3515 | J18: 5064 | K18: 9666 | L18: 1365 | M18: 3022 | N18: 15468
A19: =B19&C19 -> EnterpriseAccounting | B19: Enterprise | C19: Accounting | E19: 9098 | F19: 19683 | G19: 55827 | H19: 6756 | I19: 18760 | J19: 15933 | K19: 6528 | L19: 68814 | M19: 32694 | N19: 9172
C20: Total | E20: =SUM(E18:E19) -> 9782 | F20: =SUM(F18:F19) -> 37365 | G20: =SUM(G18:G19) -> 65967 | H20: =SUM(H18:H19) -> 10008 | I20: =SUM(I18:I19) -> 22275 | J20: =SUM(J18:J19) -> 20997 | K20: =SUM(K18:K19) -> 16194 | L20: =SUM(L18:L19) -> 70179 | ... N20: =SUM(N18:N19) -> 24640
B23: Total Revenue | E23: =SUM(E9,E14,E20) -> 65180 | F23: =SUM(F9,F14,F20) -> 165112 | G23: =SUM(G9,G14,G20) -> 112577 | H23: =SUM(H9,H14,H20) -> 153933 | I23: =SUM(I9,I14,I20) -> 157764 | J23: =SUM(J9,J14,J20) -> 172299 | K23: =SUM(K9,K14,K20) -> 134186 | L23: =SUM(L9,L14,L20) -> 169064 | ... N23: =SUM(N9,N14,N20) -> 199582

Sheet Financials Canada
D1: Year | E1: 2018 | F1: 2019 | G1: 2020 | H1: 2021 | I1: 2022 | J1: 2023 | K1: 2024 | L1: 2025 | M1: 2026 | N1: 2027
D2: Period start | F2: 43466 | G2: 43831 | H2: 44197 | I2: 44562 | J2: 44927 | K2: 45292 | L2: 45658 | M2: 46023 | N2: 46388
D3: Period end | E3: 43465 | F3: 43830 | G3: 44196 | H3: 44561 | I3: 44926 | J3: 45291 | K3: 45657 | L3: 46022 | M3: 46387 | N3: 46752
A6: Index Key | B6: Customer | C6: Service
A7: =B7&C7 -> SMBArtificial Intelligence | B7: SMB | C7: Artificial Intelligence | E7: 1869 | F7: 3211 | G7: 2405 | H7: 2490 | I7: 3789 | J7: 2298 | K7: 4440 | L7: 4901 | M7: 3828 | N7: 1808
A8: =B8&C8 -> EnterpriseArtificial Intelligence | B8: Enterprise | C8: Artificial Intelligence | E8: 7987 | F8: 7978 | G8: 8045 | H8: 5075 | I8: 7242 | J8: 9330 | K8: 6979 | L8: 8809 | M8: 8073 | N8: 7814
C9: Total | E9: =SUM(E7:E8) -> 9856 | F9: =SUM(F7:F8) -> 11189 | G9: =SUM(G7:G8) -> 10450 | H9: =SUM(H7:H8) -> 7565 | I9: =SUM(I7:I8) -> 11031 | J9: =SUM(J7:J8) -> 11628 | K9: =SUM(K7:K8) -> 11419 | L9: =SUM(L7:L8) -> 13710 | ... N9: =SUM(N7:N8) -> 9622
A10: =B10&C10
A11: =B11&C11
A12: =B12&C12 -> SMBMarketing | B12: SMB | C12: Marketing | E12: 2184 | F12: 1395 | G12: 1625 | H12: 1710 | I12: 1738 | J12: 2471 | K12: 1689 | L12: 2300 | M12: 3500 | N12: 2150
A13: =B13&C13 -> EnterpriseMarketing | B13: Enterprise | C13: Marketing | E13: 3902 | F13: 3286 | G13: 2912 | H13: 4586 | I13: 2666 | J13: 4027 | K13: 2778 | L13: 5369 | M13: 4109 | N13: 3706
C14: Total | E14: =SUM(E12:E13) -> 6086 | F14: 4682 | G14: 4537 | H14: 6296 | I14: 4404 | J14: 6498 | K14: 4467 | L14: 7670 | M14: 6610 | N14: 5856
A15: =B15&C15
A16: =B16&C16
A17: =B17&C17
A18: =B18&C18 -> SMBAccounting | B18: SMB | C18: Accounting | E18: 684 | F18: 2947 | G18: 1690 | H18: 1626 | I18: 3515 | J18: 2532 | K18: 1611 | L18: 455 | M18: 3022 | N18: 3867
A19: =B19&C19 -> EnterpriseAccounting | B19: Enterprise | C19: Accounting | E19: 4549 | F19: 2187 | G19: 6203 | H19: 1126 | I19: 4690 | J19: 5311 | K19: 6528 | L19: 7646 | M19: 5449 | N19: 4586
C20: Total | E20: =SUM(E18:E19) -> 5233 | F20: =SUM(F18:F19) -> 5134 | G20: =SUM(G18:G19) -> 7893 | H20: =SUM(H18:H19) -> 2752 | I20: =SUM(I18:I19) -> 8205 | J20: =SUM(J18:J19) -> 7843 | K20: =SUM(K18:K19) -> 8139 | L20: =SUM(L18:L19) -> 8101 | ... N20: =SUM(N18:N19) -> 8453
B23: Total Revenue | E23: =SUM(E9,E14,E20) -> 21175 | F23: =SUM(F9,F14,F20) -> 21005 | G23: =SUM(G9,G14,G20) -> 22880 | H23: =SUM(H9,H14,H20) -> 16613 | I23: =SUM(I9,I14,I20) -> 23640 | J23: =SUM(J9,J14,J20) -> 25969 | K23: =SUM(K9,K14,K20) -> 24025 | L23: =SUM(L9,L14,L20) -> 29481 | ... N23: =SUM(N9,N14,N20) -> 23931

Sheet Gross Profit & EBITDA
A1: Country | B1: Year | C1: Service | D1: Xlookup Key | E1: Gross Profit Margin | F1: EBITDA Margin
A2: USA | B2: 2018 | C2: Artificial Intelligence | D2: =A2&B2&C2 -> USA2018Artificial Intelligence | E2: 0.5 | F2: 0.2
A3: USA | B3: 2019 | C3: Artificial Intelligence | D3: =A3&B3&C3 -> USA2019Artificial Intelligence | E3: 0.5 | F3: 0.1
A4: USA | B4: 2020 | C4: Artificial Intelligence | D4: =A4&B4&C4 -> USA2020Artificial Intelligence | E4: 0.8 | F4: 0.2
A5: USA | B5: 2021 | C5: Artificial Intelligence | D5: =A5&B5&C5 -> USA2021Artificial Intelligence | E5: 0.6 | F5: 0.2
A6: USA | B6: 2022 | C6: Artificial Intelligence | D6: =A6&B6&C6 -> USA2022Artificial Intelligence | E6: 0.7 | F6: 0.1
A7: USA | B7: 2023 | C7: Artificial Intelligence | D7: =A7&B7&C7 -> USA2023Artificial Intelligence | E7: 0.7 | F7: 0.2
A8: USA | B8: 2024 | C8: Artificial Intelligence | D8: =A8&B8&C8 -> USA2024Artificial Intelligence | E8: 0.5 | F8: 0.2
A9: USA | B9: 2025 | C9: Artificial Intelligence | D9: =A9&B9&C9 -> USA2025Artificial Intelligence | E9: 0.6 | F9: 0.1
A10: USA | B10: 2026 | C10: Artificial Intelligence | D10: =A10&B10&C10 -> USA2026Artificial Intelligence | E10: 0.5 | F10: 0.2
A11: USA | B11: 2027 | C11: Artificial Intelligence | D11: =A11&B11&C11 -> USA2027Artificial Intelligence | E11: 0.5 | F11: 0.1
A12: USA | B12: 2018 | C12: Marketing | D12: =A12&B12&C12 -> USA2018Marketing | E12: 0.7 | F12: 0.2
A13: USA | B13: 2019 | C13: Marketing | D13: =A13&B13&C13 -> USA2019Marketing | E13: 0.5 | F13: 0.1
... A61: Canada | B61: 2027 | C61: Accounting | D61: =A61&B61&C61 -> Canada2027Accounting | E61: 0.6 | F61: 0.1
